<mujoco model="z1">
  <compiler angle="radian" meshdir="assets"/>

  <!-- <option integrator="implicitfast"/> -->
  <option timestep="0.01"/>


  <default>
    <default class="z1">
      <!-- <joint damping="1" frictionloss="1"/> -->
      <general biastype="affine" gainprm="1000" biasprm="0 -1000 -100" forcerange="-30 30"/>
      <default class="visual">
        <geom type="mesh" group="2" contype="0" conaffinity="0"/>
      </default>
      <default class="collision">
        <geom type="box" group="3" mass="0" density="0"/>
      </default>
    </default>
  </default>

  <asset>
    <mesh file="z1_Link00.stl"/>
    <mesh file="z1_Link01.stl"/>
    <mesh file="z1_Link02.stl"/>
    <mesh file="z1_Link03.stl"/>
    <mesh file="z1_Link04.stl"/>
    <mesh file="z1_Link05.stl"/>
    <mesh file="z1_Link06.stl"/>
  </asset>

  <worldbody>
    <body name="link00" childclass="z1">
      <inertial pos="-0.00334984 -0.00013615 0.0249584" quat="-0.00692194 0.682592 0.00133293 0.730766" mass="0.472475"
        diaginertia="0.000531375 0.000415207 0.000378658"/>
      <geom class="visual" mesh="z1_Link00"/>
      <camera name="side" pos="0 -3 1" xyaxes="1 0 0 0 1 2" mode="trackcom"/>
      <geom size="0.0325 0.0325 0.0255" pos="0 0 0.0255" class="collision"/>
      <body name="link01" pos="0 0 0.0585">
        <camera name="side1" pos="0 -3 1" xyaxes="1 0 0 0 1 2" mode="trackcom"/>
        <inertial pos="2.47e-06 -0.00025198 0.0231717" quat="0.708578 0.705633 0.000281462 -0.000355927" mass="0.673326"
          diaginertia="0.00128328 0.000839362 0.000719308"/>
        <joint name="joint1" axis="0 0 1" range="-2.61799 2.61799"/>
        <geom class="visual" mesh="z1_Link01"/>
        <body name="link02" pos="0 0 0.045">
          <inertial pos="-0.110126 0.00240029 0.00158266" quat="0.00748058 0.707092 -0.0114473 0.70699" mass="1.19132"
            diaginertia="0.0246612 0.0243113 0.00100468"/>
          <joint name="joint2" axis="0 1 0" range="0 2.96706" damping="2"/>
          <geom class="visual" mesh="z1_Link02"/>
          <geom size="0.0325 0.0325 0.051" quat="1 1 0 0" class="collision"/>
          <geom size="0.0225 0.0225 0.1175" pos="-0.1625 0 0" quat="1 0 1 0" class="collision"/>
          <geom size="0.0325 0.0325 0.0255" pos="-0.35 0 0" quat="1 1 0 0" class="collision"/>
          <body name="link03" pos="-0.35 0 0">
            <inertial pos="0.106092 -0.00541815 0.0347638" quat="0.540557 0.443575 0.426319 0.573839" mass="0.839409"
              diaginertia="0.00954365 0.00938711 0.000558432"/>
            <joint name="joint3" axis="0 1 0" range="-2.87979 0"/>
            <geom class="visual" mesh="z1_Link03"/>
            <geom size="0.02 0.02 0.058" pos="0.128 0 0.055" quat="1 0 1 0" class="collision"/>
            <geom size="0.0325 0.0325 0.0295" pos="0.2205 0 0.055" quat="0.5 -0.5 0.5 0.5" class="collision"/>
            <body name="link04" pos="0.218 0 0.057">
              <inertial pos="0.0436668 0.00364738 -0.00170192" quat="0.0390835 0.726445 -0.0526787 0.684087"
                mass="0.564046" diaginertia="0.000981656 0.00094053 0.000302655"/>
              <joint name="joint4" axis="0 1 0" range="-1.51844 1.51844"/>
              <geom class="visual" mesh="z1_Link04"/>
              <geom size="0.0325 0.0325 0.0335" pos="0.072 0 0" class="collision"/>
              <body name="link05" pos="0.07 0 0">
                <inertial pos="0.0312153 0 0.00646316" quat="0.462205 0.535209 0.53785 0.45895" mass="0.389385"
                  diaginertia="0.000558961 0.000547317 0.000167332"/>
                <joint name="joint5" axis="0 0 1" range="-1.3439 1.3439"/>
                <geom class="visual" mesh="z1_Link05"/>
                <body name="link06" pos="0.0492 0 0">
                  <inertial pos="0.0241569 -0.00017355 -0.00143876" quat="0.998779 0.0457735 -0.00663717 0.0173548"
                    mass="0.288758" diaginertia="0.00018333 0.000147464 0.000146786"/>
                  <joint name="joint6" axis="1 0 0" range="-2.79253 2.79253"/>
                  <geom class="visual" mesh="z1_Link06"/>
                  <geom size="0.0325 0.0325 0.0255" pos="0.0255 0 0" quat="1 0 1 0" class="collision"/>
                </body>
              </body>
            </body>
          </body>
        </body>
      </body>
    </body>
    <body name="load" pos="0.3 0 0.05" childclass="z1">
      <freejoint name="load_joint" />
      <inertial pos="0 0 0" quat="0.0 0.0 0.0 1.0" mass="18.3" diaginertia="0.144005 0.380679 0.447682 "/>

      <geom type="box" size="0.05 0.05 0.05"  name="load_geom"/>


    </body>
  </worldbody>

  <actuator>
    <motor class="z1" name="motor1" joint="joint1" ctrlrange="-2.61799 2.61799"/>
    <motor class="z1" name="motor2" joint="joint2" ctrlrange="0 2.96706" />
    <motor class="z1" name="motor3" joint="joint3" ctrlrange="-2.87979 0"/>
    <motor class="z1" name="motor4" joint="joint4" ctrlrange="-1.51844 1.51844"/>
    <motor class="z1" name="motor5" joint="joint5" ctrlrange="-1.3439 1.3439"/>
    <motor class="z1" name="motor6" joint="joint6" ctrlrange="-2.79253 2.79253"/>
  </actuator>
  <contact>
    <exclude body1="link00" body2="link02" />
    <exclude body1="link00" body2="link03" />
    <exclude body1="link00" body2="link04" />
    <exclude body1="link00" body2="link05" />
    <exclude body1="link00" body2="link06" />

    <exclude body1="link01" body2="link02" />
    <exclude body1="link01" body2="link03" />
    <exclude body1="link01" body2="link04" />
    <exclude body1="link01" body2="link05" />
    <exclude body1="link01" body2="link06" />

    <exclude body1="link02" body2="link03" />
    <exclude body1="link02" body2="link04" />
    <exclude body1="link02" body2="link05" />
    <exclude body1="link02" body2="link06" />


    <exclude body1="link03" body2="link04" />
    <exclude body1="link03" body2="link05" />
    <exclude body1="link03" body2="link06" />



    <exclude body1="link04" body2="link05" />
    <exclude body1="link04" body2="link06" />

    <exclude body1="link05" body2="link06" />

  </contact>
  <!-- <keyframe>
    <key name="home" qpos="0 0.785 -0.261 -0.523 0 0" ctrl="0 0.785 -0.261 -0.523 0 0"/>
  </keyframe> -->
</mujoco>

