<mujoco model="z1">
  <compiler angle="radian" meshdir="assets"/>

  <!-- <option integrator="implicitfast"/> -->
  <option timestep="0.01"/>


  <default>
    <default class="z1">
      <!-- <joint damping="1" frictionloss="1"/> -->
      <general biastype="affine" gainprm="1000" biasprm="0 -1000 -100" forcerange="-30 30"/>
      <default class="visual">
        <geom type="mesh" group="2" contype="0" conaffinity="0"/>
      </default>
      <default class="collision">
        <geom type="box" group="3" mass="0" density="0"/>
      </default>
    </default>
  </default>

  <asset>
    <mesh file="z1_Link00.stl"/>
    <mesh file="z1_Link01.stl"/>
    <mesh file="z1_Link02.stl"/>
    <mesh file="z1_Link03.stl"/>
    <mesh file="z1_Link04.stl"/>
    <mesh file="z1_Link05.stl"/>
    <mesh file="z1_Link06.stl"/>
  </asset>







  <default>
    <default class="2f85">
      <mesh scale="0.001 0.001 0.001"/>
      <general biastype="affine"/>

      <joint axis="1 0 0"/>
      <default class="driver">
        <joint range="0 0.8" armature="0.005" damping="0.1" solimplimit="0.95 0.99 0.001" solreflimit="0.005 1"/>
      </default>
      <default class="follower">
        <joint range="-0.872664 0.872664" armature="0.001" pos="0 -0.018 0.0065" solimplimit="0.95 0.99 0.001" solreflimit="0.005 1"/>
      </default>
      <default class="spring_link">
        <joint range="-0.29670597283 0.8" armature="0.001" stiffness="0.05" springref="2.62" damping="0.00125"/>
      </default>
      <default class="coupler">
        <joint range="-1.57 0" armature="0.001" solimplimit="0.95 0.99 0.001" solreflimit="0.005 1"/>
      </default>

      <!-- <default class="visual">
        <geom type="mesh" contype="0" conaffinity="0" group="2"/>
      </default> -->
      <default class="collision_finger">
        <geom type="mesh" group="3"/>
        <default class="pad_box1">
          <geom mass="0" type="box" pos="0 -0.0026 0.028125" size="0.011 0.004 0.009375" friction="0.7"
            solimp="0.95 0.99 0.001" solref="0.004 1" priority="1" rgba="0.55 0.55 0.55 1"/>
        </default>
        <default class="pad_box2">
          <geom mass="0" type="box" pos="0 -0.0026 0.009375" size="0.011 0.004 0.009375" friction="0.6"
            solimp="0.95 0.99 0.001" solref="0.004 1" priority="1" rgba="0.45 0.45 0.45 1"/>
        </default>
      </default>
    </default>
  </default>
  <asset>
    <material name="metal" rgba="0.58 0.58 0.58 1"/>
    <material name="silicone" rgba="0.1882 0.1882 0.1882 1"/>
    <material name="gray" rgba="0.4627 0.4627 0.4627 1"/>
    <material name="black" rgba="0.149 0.149 0.149 1"/>

    <mesh class="2f85" file="base_mount.stl"/>
    <mesh class="2f85" file="base.stl"/>
    <mesh class="2f85" file="driver.stl"/>
    <mesh class="2f85" file="coupler.stl"/>
    <mesh class="2f85" file="follower.stl"/>
    <mesh class="2f85" file="pad.stl"/>
    <mesh class="2f85" file="silicone_pad.stl"/>
    <mesh class="2f85" file="spring_link.stl"/>
  </asset>







  <worldbody>
    <body name="link00" childclass="z1">
      <inertial pos="-0.00334984 -0.00013615 0.0249584" quat="-0.00692194 0.682592 0.00133293 0.730766" mass="0.472475"
        diaginertia="0.000531375 0.000415207 0.000378658"/>
      <geom class="visual" mesh="z1_Link00"/>
      <camera name="side" pos="0 -3 1" xyaxes="1 0 0 0 1 2" mode="trackcom"/>
      <geom size="0.0325 0.0325 0.0255" pos="0 0 0.0255" class="collision"/>
      <body name="link01" pos="0 0 0.0585">
        <camera name="side1" pos="0 -3 1" xyaxes="1 0 0 0 1 2" mode="trackcom"/>
        <inertial pos="2.47e-06 -0.00025198 0.0231717" quat="0.708578 0.705633 0.000281462 -0.000355927" mass="0.673326"
          diaginertia="0.00128328 0.000839362 0.000719308"/>
        <joint name="joint1" axis="0 0 1" range="-2.61799 2.61799"/>
        <geom class="visual" mesh="z1_Link01"/>
        <body name="link02" pos="0 0 0.045">
          <inertial pos="-0.110126 0.00240029 0.00158266" quat="0.00748058 0.707092 -0.0114473 0.70699" mass="1.19132"
            diaginertia="0.0246612 0.0243113 0.00100468"/>
          <joint name="joint2" axis="0 1 0" range="0 2.96706" damping="2"/>
          <geom class="visual" mesh="z1_Link02"/>
          <geom size="0.0325 0.0325 0.051" quat="1 1 0 0" class="collision"/>
          <geom size="0.0225 0.0225 0.1175" pos="-0.1625 0 0" quat="1 0 1 0" class="collision"/>
          <geom size="0.0325 0.0325 0.0255" pos="-0.35 0 0" quat="1 1 0 0" class="collision"/>
          <body name="link03" pos="-0.35 0 0">
            <inertial pos="0.106092 -0.00541815 0.0347638" quat="0.540557 0.443575 0.426319 0.573839" mass="0.839409"
              diaginertia="0.00954365 0.00938711 0.000558432"/>
            <joint name="joint3" axis="0 1 0" range="-2.87979 0"/>
            <geom class="visual" mesh="z1_Link03"/>
            <geom size="0.02 0.02 0.058" pos="0.128 0 0.055" quat="1 0 1 0" class="collision"/>
            <geom size="0.0325 0.0325 0.0295" pos="0.2205 0 0.055" quat="0.5 -0.5 0.5 0.5" class="collision"/>
            <body name="link04" pos="0.218 0 0.057">
              <inertial pos="0.0436668 0.00364738 -0.00170192" quat="0.0390835 0.726445 -0.0526787 0.684087"
                mass="0.564046" diaginertia="0.000981656 0.00094053 0.000302655"/>
              <joint name="joint4" axis="0 1 0" range="-1.51844 1.51844"/>
              <geom class="visual" mesh="z1_Link04"/>
              <geom size="0.0325 0.0325 0.0335" pos="0.072 0 0" class="collision"/>
              <body name="link05" pos="0.07 0 0">
                <inertial pos="0.0312153 0 0.00646316" quat="0.462205 0.535209 0.53785 0.45895" mass="0.389385"
                  diaginertia="0.000558961 0.000547317 0.000167332"/>
                <joint name="joint5" axis="0 0 1" range="-1.3439 1.3439"/>
                <geom class="visual" mesh="z1_Link05"/>
                <body name="link06" pos="0.0492 0 0">
                  <inertial pos="0.0241569 -0.00017355 -0.00143876" quat="0.998779 0.0457735 -0.00663717 0.0173548"
                    mass="0.288758" diaginertia="0.00018333 0.000147464 0.000146786"/>
                  <joint name="joint6" axis="1 0 0" range="-2.79253 2.79253"/>
                  <geom class="visual" mesh="z1_Link06"/>
                  <geom size="0.0325 0.0325 0.0255" pos="0.0255 0 0" quat="1 0 1 0" class="collision"/>
                 
                  <body name="base_mount" pos="0.05 0 0.007" euler="0 1.57 0" childclass="2f85">
                    <geom class="visual" mesh="base_mount" material="black"/>
                    <geom class="collision_finger" mesh="base_mount"/>
                    <body name="base" pos="0 0 0.0038" quat="1 0 0 -1">
                      <inertial mass="0.777441" pos="0 -2.70394e-05 0.0354675" quat="1 -0.00152849 0 0"
                        diaginertia="0.000260285 0.000225381 0.000152708"/>
                      <geom class="visual" mesh="base" material="black"/>
                      <geom class="collision_finger" mesh="base"/>
                      <site name="pinch" pos="0 0 0.145" type="sphere" group="5" rgba="0.9 0.9 0.9 1" size="0.005"/>
                      <!-- Right-hand side 4-bar linkage -->
                      <body name="right_driver" pos="0 0.0306011 0.054904">
                        <inertial mass="0.00899563" pos="2.96931e-12 0.0177547 0.00107314" quat="0.681301 0.732003 0 0"
                          diaginertia="1.72352e-06 1.60906e-06 3.22006e-07"/>
                        <joint name="right_driver_joint" class="driver"/>
                        <geom class="visual" mesh="driver" material="gray"/>
                        <geom class="collision_finger" mesh="driver"/>
                        <body name="right_coupler" pos="0 0.0315 -0.0041">
                          <inertial mass="0.0140974" pos="0 0.00301209 0.0232175" quat="0.705636 -0.0455904 0.0455904 0.705636"
                            diaginertia="4.16206e-06 3.52216e-06 8.88131e-07"/>
                          <joint name="right_coupler_joint" class="coupler"/>
                          <geom class="visual" mesh="coupler" material="black"/>
                          <geom class="collision_finger" mesh="coupler"/>
                        </body>
                      </body>
                      <body name="right_spring_link" pos="0 0.0132 0.0609">
                        <inertial mass="0.0221642" pos="-8.65005e-09 0.0181624 0.0212658" quat="0.663403 -0.244737 0.244737 0.663403"
                          diaginertia="8.96853e-06 6.71733e-06 2.63931e-06"/>
                        <joint name="right_spring_link_joint" class="spring_link"/>
                        <geom class="visual" mesh="spring_link" material="black"/>
                        <geom class="collision_finger" mesh="spring_link"/>
                        <body name="right_follower" pos="0 0.055 0.0375">
                          <inertial mass="0.0125222" pos="0 -0.011046 0.0124786" quat="1 0.1664 0 0"
                            diaginertia="2.67415e-06 2.4559e-06 6.02031e-07"/>
                          <joint name="right_follower_joint" class="follower"/>
                          <geom class="visual" mesh="follower" material="black"/>
                          <geom class="collision_finger" mesh="follower"/>
                          <body name="right_pad" pos="0 -0.0189 0.01352">
                            <geom class="pad_box1" name="right_pad1"/>
                            <geom class="pad_box2" name="right_pad2"/>
                            <inertial mass="0.0035" pos="0 -0.0025 0.0185" quat="0.707107 0 0 0.707107"
                              diaginertia="4.73958e-07 3.64583e-07 1.23958e-07"/>
                            <geom class="visual" mesh="pad"/>
                            <body name="right_silicone_pad">
                              <geom class="visual" mesh="silicone_pad" material="black"/>
                            </body>
                          </body>
                        </body>
                      </body>
                      <!-- Left-hand side 4-bar linkage -->
                      <body name="left_driver" pos="0 -0.0306011 0.054904" quat="0 0 0 1">
                        <inertial mass="0.00899563" pos="0 0.0177547 0.00107314" quat="0.681301 0.732003 0 0"
                          diaginertia="1.72352e-06 1.60906e-06 3.22006e-07"/>
                        <joint name="left_driver_joint" class="driver"/>
                        <geom class="visual" mesh="driver" material="gray"/>
                        <geom class="collision_finger" mesh="driver"/>
                        <body name="left_coupler" pos="0 0.0315 -0.0041">
                          <inertial mass="0.0140974" pos="0 0.00301209 0.0232175" quat="0.705636 -0.0455904 0.0455904 0.705636"
                            diaginertia="4.16206e-06 3.52216e-06 8.88131e-07"/>
                          <joint name="left_coupler_joint" class="coupler"/>
                          <geom class="visual" mesh="coupler" material="black"/>
                          <geom class="collision_finger" mesh="coupler"/>
                        </body>
                      </body>
                      <body name="left_spring_link" pos="0 -0.0132 0.0609" quat="0 0 0 1">
                        <inertial mass="0.0221642" pos="-8.65005e-09 0.0181624 0.0212658" quat="0.663403 -0.244737 0.244737 0.663403"
                          diaginertia="8.96853e-06 6.71733e-06 2.63931e-06"/>
                        <joint name="left_spring_link_joint" class="spring_link"/>
                        <geom class="visual" mesh="spring_link" material="black"/>
                        <geom class="collision_finger" mesh="spring_link"/>
                        <body name="left_follower" pos="0 0.055 0.0375">
                          <inertial mass="0.0125222" pos="0 -0.011046 0.0124786" quat="1 0.1664 0 0"
                            diaginertia="2.67415e-06 2.4559e-06 6.02031e-07"/>
                          <joint name="left_follower_joint" class="follower"/>
                          <geom class="visual" mesh="follower" material="black"/>
                          <geom class="collision_finger" mesh="follower"/>
                          <body name="left_pad" pos="0 -0.0189 0.01352">
                            <geom class="pad_box1" name="left_pad1"/>
                            <geom class="pad_box2" name="left_pad2"/>
                            <inertial mass="0.0035" pos="0 -0.0025 0.0185" quat="1 0 0 1"
                              diaginertia="4.73958e-07 3.64583e-07 1.23958e-07"/>
                            <geom class="visual" mesh="pad"/>
                            <body name="left_silicone_pad">
                              <geom class="visual" mesh="silicone_pad" material="black"/>
                            </body>
                          </body>
                        </body>
                      </body>
                    </body>
                  </body>

                </body>
              </body>
            </body>
          </body>
        </body>
      </body>
    </body>
    <body name="load" pos="0.3 0 0.05" childclass="z1">
      <freejoint name="load_joint" />
      <inertial pos="0 0 0" quat="0.0 0.0 0.0 1.0" mass="0.3" diaginertia="0.144005 0.380679 0.447682 "/>

      <geom type="box" size="0.02 0.02 0.02"  name="load_geom"/>


    </body>
  </worldbody>

  <actuator>
    <motor class="z1" name="motor1" joint="joint1" ctrlrange="-2.61799 2.61799"/>
    <motor class="z1" name="motor2" joint="joint2" ctrlrange="0 2.96706" />
    <motor class="z1" name="motor3" joint="joint3" ctrlrange="-20.87979 0"/>
    <motor class="z1" name="motor4" joint="joint4" ctrlrange="-10.51844 10.51844"/>
    <motor class="z1" name="motor5" joint="joint5" ctrlrange="-1.3439 1.3439"/>
    <motor class="z1" name="motor6" joint="joint6" ctrlrange="-2.79253 2.79253"/>
  </actuator>
  <contact>
    <!-- <exclude body1="link00" body2="link02" />
    <exclude body1="link00" body2="link03" />
    <exclude body1="link00" body2="link04" />
    <exclude body1="link00" body2="link05" />
    <exclude body1="link00" body2="link06" />

    <exclude body1="link01" body2="link02" />
    <exclude body1="link01" body2="link03" />
    <exclude body1="link01" body2="link04" />
    <exclude body1="link01" body2="link05" />
    <exclude body1="link01" body2="link06" />

    <exclude body1="link02" body2="link03" />
    <exclude body1="link02" body2="link04" />
    <exclude body1="link02" body2="link05" />
    <exclude body1="link02" body2="link06" />


    <exclude body1="link03" body2="link04" />
    <exclude body1="link03" body2="link05" />
    <exclude body1="link03" body2="link06" />



    <exclude body1="link04" body2="link05" />
    <exclude body1="link04" body2="link06" />

    <exclude body1="link05" body2="link06" /> -->

  </contact>

    <contact>
    <exclude body1="base" body2="left_driver"/>
    <exclude body1="base" body2="right_driver"/>
    <exclude body1="base" body2="left_spring_link"/>
    <exclude body1="base" body2="right_spring_link"/>
    <exclude body1="right_coupler" body2="right_follower"/>
    <exclude body1="left_coupler" body2="left_follower"/>
    <exclude body1="base_mount" body2="link01"/>
    <exclude body1="base_mount" body2="link02"/>

    <exclude body1="base" body2="link05"/>
    <exclude body1="base" body2="link04"/>
    <exclude body1="base" body2="link03"/>
    <exclude body1="base" body2="link02"/>
    <exclude body1="base" body2="link01"/>
    <exclude body1="base" body2="link00"/>

                        <!-- <exclude body1="base" body2="link05"/>
                            <exclude body1="base" body2="link05"/>
                                <exclude body1="base" body2="link05"/> -->
  </contact>


    <tendon>
    <fixed name="split">
      <joint joint="right_driver_joint" coef="0.5"/>
      <joint joint="left_driver_joint" coef="0.5"/>
    </fixed>
  </tendon>

  <equality>
    <connect anchor="0 0 0" body1="right_follower" body2="right_coupler" solimp="0.95 0.99 0.001" solref="0.005 1"/>
    <connect anchor="0 0 0" body1="left_follower" body2="left_coupler" solimp="0.95 0.99 0.001" solref="0.005 1"/>
    <joint joint1="right_driver_joint" joint2="left_driver_joint" polycoef="0 1 0 0 0" solimp="0.95 0.99 0.001"
      solref="0.005 1"/>
  </equality>

  <!--
    The general actuator below is a customized position actuator (with some damping) where
    gainprm[0] != kp (see http://mujoco.org/book/modeling.html#position).
    The reason why gainprm[0] != kp is because the control input range has to be re-scaled to
    [0, 255]. The joint range is currently set at [0, 0.8], the control range is [0, 255] and
    kp = 100. Tau = Kp * scale * control_input - Kp * error, max(Kp * scale * control_input) = 0.8,
    hence scale = 0.8 * 100 / 255
  -->
  <actuator>
    <general class="2f85" name="fingers_actuator" tendon="split" forcerange="-5 5" ctrlrange="0 255"
      gainprm="0.3137255 0 0" biasprm="0 -100 -10"/>
  </actuator>
  <!-- <keyframe>
    <key name="home" qpos="0 0.785 -0.261 -0.523 0 0" ctrl="0 0.785 -0.261 -0.523 0 0"/>
  </keyframe> -->
</mujoco>

